Workbook

Sheet Financial Ratios
A4: Yeti Holdings, Key Financial Ratios
A5: Your Name: | B5: William Wallace
J6: 2023, 2024
A7: DuPont Ratios | B7: 2018 | C7: 2019 | D7: 2020 | E7: 2021 | F7: 2022 | G7: 2023 | H7: 2024 | I7: Mean | J7: Mean
A8: Net Profit Margin (NIAT/Net Revenues) | B8: ='Income Statements'!B16/'Income Statements'!B6 -> 0.074166092 | C8: ='Income Statements'!C16/'Income Statements'!C6 -> 0.055195495 | D8: ='Income Statements'!D16/'Income Statements'!D6 -> 0.14271137 | E8: ='Income Statements'!E16/'Income Statements'!E6 -> 0.15067587 | F8: ='Income Statements'!F16/'Income Statements'!F6 -> 0.05622603 | G8: ='Income Statements'!G16/'Income Statements'!G6 -> 0.10241977 | H8: ='Income Statements'!H16/'Income Statements'!H6 -> 0.096011581 | I8: =AVERAGE(B8:H8) -> 0.096772316 | J8: =AVERAGE(G8:H8) -> 0.099215674
A9: Total Asset Turnover (Net Revenue/ Total Assets) | B9: ='Income Statements'!B6/'Balance Sheets'!B19 -> 1.5146116 | C9: ='Income Statements'!C6/'Balance Sheets'!C19 -> 1.4514335 | D9: ='Income Statements'!D6/'Balance Sheets'!D19 -> 1.4811693 | E9: ='Income Statements'!E6/'Balance Sheets'!E19 -> 1.2869713 | F9: ='Income Statements'!F6/'Balance Sheets'!F19 -> 1.481495 | G9: ='Income Statements'!G6/'Balance Sheets'!G19 -> 1.2786951 | H9: ='Income Statements'!H6/'Balance Sheets'!H19 -> 1.4227856 | I9: =AVERAGE(B9:H9) -> 1.4167373 | J9: =AVERAGE(G9:H9) -> 1.3507403
A10: Leverage (Total Assets/Total Equity) | B10: ='Balance Sheets'!B19/'Balance Sheets'!B44 -> 17.749232 | C10: ='Balance Sheets'!C19/'Balance Sheets'!C44 -> 5.1599443 | D10: ='Balance Sheets'!D19/'Balance Sheets'!D44 -> 2.5555513 | E10: ='Balance Sheets'!E19/'Balance Sheets'!E44 -> 2.1172563 | F10: ='Balance Sheets'!F19/'Balance Sheets'!F44 -> 2.045227 | G10: ='Balance Sheets'!G19/'Balance Sheets'!G44 -> 1.7926673 | H10: ='Balance Sheets'!H19/'Balance Sheets'!H44 -> 1.7377487 | I10: =AVERAGE(B10:H10) -> 4.7368039 | J10: =AVERAGE(G10:H10) -> 1.765208
A11: Return on Total Assets | B11: =B8*B9 -> 0.11233283 | C11: =C8*C9 -> 0.08011259 | D11: =D8*D9 -> 0.2113797 | E11: =E8*E9 -> 0.19391552 | F11: =F8*F9 -> 0.083298584 | G11: =G8*G9 -> 0.13096365 | H11: =H8*H9 -> 0.13660389 | I11: =AVERAGE(B11:H11) -> 0.13551525 | J11: =AVERAGE(G11:H11) -> 0.13378377
A12: Return on Equity | B12: =B8*B9*B10 -> 1.9938214 | C12: =C8*C9*C10 -> 0.4133765 | D12: =D8*D9*D10 -> 0.54019167 | E12: =E8*E9*E10 -> 0.41056886 | F12: =F8*F9*F10 -> 0.17036452 | G12: =G8*G9*G10 -> 0.23477426 | H12: =H8*H9*H10 -> 0.23738324 | I12: =AVERAGE(B12:H12) -> 0.57149721 | J12: =AVERAGE(G12:H12) -> 0.23607875
A14: Profitability
A15: Gross Profit Margin | B15: ='Income Statements'!B8/'Income Statements'!B6 -> 0.49192574 | C15: ='Income Statements'!C8/'Income Statements'!C6 -> 0.52018859 | D15: ='Income Statements'!D8/'Income Statements'!D6 -> 0.57597408 | E15: ='Income Statements'!E8/'Income Statements'!E6 -> 0.57839785 | F15: ='Income Statements'!F8/'Income Statements'!F6 -> 0.47855471 | G15: ='Income Statements'!G8/'Income Statements'!G6 -> 0.56862519 | H15: ='Income Statements'!H8/'Income Statements'!H6 -> 0.58106983 | I15: =AVERAGE(B15:H15) -> 0.54210514 | J15: =AVERAGE(G15:H15) -> 0.57484751
A16: EBIT Margin | B16: ='Income Statements'!B11/'Income Statements'!B6 -> 0.13116547 | C16: ='Income Statements'!C11/'Income Statements'!C6 -> 0.098246317 | D16: ='Income Statements'!D11/'Income Statements'!D6 -> 0.1962342 | E16: ='Income Statements'!E11/'Income Statements'!E6 -> 0.19485481 | F16: ='Income Statements'!F11/'Income Statements'!F6 -> 0.079212172 | G16: ='Income Statements'!G11/'Income Statements'!G6 -> 0.13592345 | H16: ='Income Statements'!H11/'Income Statements'!H6 -> 0.13409455 | I16: =AVERAGE(B16:H16) -> 0.138533 | J16: =AVERAGE(G16:H16) -> 0.135009
A17: EBT Margin | B17: ='Income Statements'!B14/'Income Statements'!B6 -> 0.089383732 | C17: ='Income Statements'!C14/'Income Statements'!C6 -> 0.073607855 | D17: ='Income Statements'!D14/'Income Statements'!D6 -> 0.18796103 | E17: ='Income Statements'!E14/'Income Statements'!E6 -> 0.19022827 | F17: ='Income Statements'!F14/'Income Statements'!F6 -> 0.072828108 | G17: ='Income Statements'!G14/'Income Statements'!G6 -> 0.13621766 | H17: ='Income Statements'!H14/'Income Statements'!H6 -> 0.12724818 | I17: =AVERAGE(B17:H17) -> 0.12535355 | J17: =AVERAGE(G17:H17) -> 0.13173292
A18: NIAT Margin | B18: ='Income Statements'!B16/'Income Statements'!B6 -> 0.074166092 | C18: ='Income Statements'!C16/'Income Statements'!C6 -> 0.055195495 | D18: ='Income Statements'!D16/'Income Statements'!D6 -> 0.14271137 | E18: ='Income Statements'!E16/'Income Statements'!E6 -> 0.15067587 | F18: ='Income Statements'!F16/'Income Statements'!F6 -> 0.05622603 | G18: ='Income Statements'!G16/'Income Statements'!G6 -> 0.10241977 | H18: ='Income Statements'!H16/'Income Statements'!H6 -> 0.096011581 | I18: =AVERAGE(B18:H18) -> 0.096772316 | J18: =AVERAGE(G18:H18) -> 0.099215674
A20: Efficiency
A21: Accounts Receivable Turnover | B21: NA | C21: ='Income Statements'!C6/'Balance Sheets'!C6 -> 12.868043 | D21: ='Income Statements'!D6/'Balance Sheets'!D6 -> 14.742527 | E21: ='Income Statements'!E6/'Balance Sheets'!E6 -> 16.130474 | F21: ='Income Statements'!F6/'Balance Sheets'!F6 -> 16.8828 | G21: ='Income Statements'!G6/'Balance Sheets'!G6 -> 18.932919 | H21: ='Income Statements'!H6/'Balance Sheets'!H6 -> 16.946093 | I21: =AVERAGE(B21:H21) -> 16.083809 | J21: =AVERAGE(G21:H21) -> 17.939506
A22: Inventory Turnover | B22: NA | C22: ='Income Statements'!C8/'Balance Sheets'!C8 -> 2.8709211 | D22: ='Income Statements'!D8/'Balance Sheets'!D8 -> 3.8599249 | E22: ='Income Statements'!E8/'Balance Sheets'!E8 -> 3.5562416 | F22: ='Income Statements'!F8/'Balance Sheets'!F8 -> 2.2118718 | G22: ='Income Statements'!G8/'Balance Sheets'!G8 -> 2.6620361 | H22: ='Income Statements'!H8/'Balance Sheets'!H8 -> 3.2854622 | I22: =AVERAGE(C22:H22) -> 3.0744096 | J22: =AVERAGE(G22:H22) -> 2.9737492
A23: Long Term Assets Turnover | B23: NA | C23: ='Income Statements'!C6/'Balance Sheets'!C18 -> 3.7587373 | D23: ='Income Statements'!D6/'Balance Sheets'!D18 -> 4.1231093 | E23: ='Income Statements'!E6/'Balance Sheets'!E18 -> 10.459286 | F23: ='Income Statements'!F6/'Balance Sheets'!F18 -> 8.6913896 | G23: ='Income Statements'!G6/'Balance Sheets'!G18 -> 4.4791826 | H23: ='Income Statements'!H6/'Balance Sheets'!H18 -> 4.345764 | I23: =AVERAGE(B23:H23) -> 5.9762447 | J23: =AVERAGE(G23:H23) -> 4.4124733
A25: Capital Structure (Solvency)
A26: Total Debt to Total Assets | B26: ='Balance Sheets'!B35/'Balance Sheets'!B19 -> 0.94365953 | C26: ='Balance Sheets'!C35/'Balance Sheets'!C19 -> 0.80619946 | D26: ='Balance Sheets'!D35/'Balance Sheets'!D19 -> 0.608695 | E26: ='Balance Sheets'!E35/'Balance Sheets'!E19 -> 0.52769062 | F26: ='Balance Sheets'!F35/'Balance Sheets'!F19 -> 0.51105673 | G26: ='Balance Sheets'!G35/'Balance Sheets'!G19 -> 0.44217201 | H26: ='Balance Sheets'!H35/'Balance Sheets'!H19 -> 0.42454281 | I26: =AVERAGE(B26:H26) -> 0.60914517 | J26: =AVERAGE(G26:H26) -> 0.43335741
A27: Long Term Debt to Equity | B27: ='Balance Sheets'!B33/'Balance Sheets'!B44 -> 10.282835 | C27: ='Balance Sheets'!C33/'Balance Sheets'!C44 -> 2.7640015 | D27: ='Balance Sheets'!D33/'Balance Sheets'!D44 -> 0.5578362 | E27: ='Balance Sheets'!E33/'Balance Sheets'!E44 -> 0.33762116 | F27: ='Balance Sheets'!F33/'Balance Sheets'!F44 -> 0.26828902 | G27: ='Balance Sheets'!G33/'Balance Sheets'!G44 -> 0.24215945 | H27: ='Balance Sheets'!H33/'Balance Sheets'!H44 -> 0.22497963 | I27: =AVERAGE(B27:H27) -> 2.0968174 | J27: =AVERAGE(G27:H27) -> 0.23356954
A29: Liquidity
A30: Current Ratio | B30: ='Balance Sheets'!B10/'Balance Sheets'!B28 -> 1.5854392 | C30: ='Balance Sheets'!C10/'Balance Sheets'!C28 -> 2.1169794 | D30: ='Balance Sheets'!D10/'Balance Sheets'!D28 -> 1.6558891 | E30: ='Balance Sheets'!E10/'Balance Sheets'!E28 -> 2.6928239 | F30: ='Balance Sheets'!F10/'Balance Sheets'!F28 -> 1.7575787 | G30: ='Balance Sheets'!G10/'Balance Sheets'!G28 -> 2.2954641 | H30: ='Balance Sheets'!H10/'Balance Sheets'!H28 -> 2.1785436 | I30: =AVERAGE(B30:H30) -> 2.0403883 | J30: =AVERAGE(G30:H30) -> 2.2370038
A31: Acid Test Ratio | B31: =('Balance Sheets'!B10-'Balance Sheets'!B7)/'Balance Sheets'!B28 -> 0.80917913 | C31: =('Balance Sheets'!C10-'Balance Sheets'!C7)/'Balance Sheets'!C28 -> 1.0266276 | D31: =('Balance Sheets'!D10-'Balance Sheets'!D7)/'Balance Sheets'!D28 -> 1.1689852 | E31: =('Balance Sheets'!E10-'Balance Sheets'!E7)/'Balance Sheets'!E28 -> 1.9029954 | F31: =('Balance Sheets'!F10-'Balance Sheets'!F7)/'Balance Sheets'!F28 -> 0.84956972 | G31: =('Balance Sheets'!G10-'Balance Sheets'!G7)/'Balance Sheets'!G28 -> 1.4489586 | H31: =('Balance Sheets'!H10-'Balance Sheets'!H7)/'Balance Sheets'!H28 -> 1.3615351 | I31: =AVERAGE(B31:H31) -> 1.2239787 | J31: =AVERAGE(G31:H31) -> 1.4052468

Sheet Income Statements
A1: Yeti Holdings (YETI)
A3: Consolidated Statements Of Operations - USD ($) in Thousands
B4: 2018 | C4: 2019 | D4: 2020 | E4: 2021 | F4: 2022 | G4: 2023 | H4: 2024
A5: Income Statement
A6: Net revenue | B6: 778833 | C6: 913734 | D6: 1091721 | E6: 1410989 | F6: 1595222 | G6: 1658713 | H6: 1829873
A7: Cost of goods sold | B7: 395705 | C7: 438420 | D7: 462918 | E7: 594876 | F7: 831821 | G7: 715527 | H7: 766589
A8: Gross profit | B8: 383128 | C8: 475314 | D8: 628803 | E8: 816113 | F8: 763401 | G8: 943186 | H8: 1063284
A9: Operating expenses:
A10: Selling, General, & Administrative Expenses | B10: 280972 | C10: 385543 | D10: 414570 | E10: 541175 | F10: 637040 | G10: 717728 | H10: 817908
A11: Operating income (EBIT) | B11: 102156 | C11: 89771 | D11: 214233 | E11: 274938 | F11: 126361 | G11: 225458 | H11: 245376
A12: Interest income (expense), net | B12: -31280 | C12: -21779 | D12: -9155 | E12: -3339 | F12: -4466 | G12: -942 | H12: 660
A13: Other (expense) income, net | B13: -1261 | C13: -734 | D13: 123 | E13: -3189 | F13: -5718 | G13: 1430 | H13: -13188
A14: Income before income taxes (EBT) | B14: 69615 | C14: 67258 | D14: 205201 | E14: 268410 | F14: 116177 | G14: 225946 | H14: 232848
A15: Income tax expense | B15: -11852 | C15: -16824 | D15: -494003 | E15: -55808 | F15: -26484 | G15: -56061 | H15: -57159
A16: Net income (EAT) | B16: 57763 | C16: 50434 | D16: 155801 | E16: 212602 | F16: 89693 | G16: 169885 | H16: 175689
A17: Net income per share
A18: Basic (in dollars per share) | B18: 0.71 | C18: 0.59 | D18: 1.79 | E18: 2.43 | F18: 1.04 | G18: 1.96 | H18: 2.07
A19: Diluted (in dollars per share) | B19: 0.69 | C19: 0.58 | D19: 1.77 | E19: 2.4 | F19: 1.03 | G19: 1.94 | H19: 2.05
A20: Weighted-average common shares outstanding
A21: Basic (in shares) | B21: 81777 | C21: 85088 | D21: 86978 | E21: 87425 | F21: 86521 | G21: 86717 | H21: 84935
A22: Diluted (in shares) | B22: 83519 | C22: 86347 | D22: 87847 | E22: 88666 | F22: 87195 | G22: 87403 | H22: 85755

Sheet Balance Sheets
A1: Yeti Holdgings (YETI) | B1: 12 Months Ended
A2: Consolidated Balance Sheets - USD ($) $ in Thousands | B2: 2018 | C2: 2019 | D2: 2020 | E2: 2021 | F2: 2022 | G2: 2023 | H2: 2024
A3: Current assets:
A4: Cash | B4: 80051 | C4: 72515 | D4: 253283 | E4: 312189 | F4: 234741 | G4: 438960 | H4: 358795
A5: Accounts Receivables, net | B5: 59328 | C5: 82688 | D5: 65417 | E5: 109530 | F5: 79446 | G5: 95774 | H5: 120190
A6: Average Accounts Receivable | C6: =(C5+B5)/2 -> 71008 | D6: =(D5+C5)/2 -> 74052.5 | E6: =(E5+D5)/2 -> 87473.5 | F6: =(F5+E5)/2 -> 94488 | G6: =(G5+F5)/2 -> 87610 | H6: =(H5+G5)/2 -> 107982
A7: Inventory | B7: 145423 | C7: 185700 | D7: 140111 | E7: 318864 | F7: 371412 | G7: 337208 | H7: 310058
A8: Average Inventory | B8: na | C8: =(C7+B7)/2 -> 165561.5 | D8: =(D7+C7)/2 -> 162905.5 | E8: =(E7+D7)/2 -> 229487.5 | F8: =(F7+E7)/2 -> 345138 | G8: =(G7+F7)/2 -> 354310 | H8: =(H7+G7)/2 -> 323633
A9: Prepaid expenses and other current assets | B9: 12211 | C9: 19644 | D9: 17686 | E9: 29584 | F9: 33321 | G9: 42463 | H9: 37723
A10: CURRENT ASSETS | B10: 297013 | C10: 360547 | D10: 476497 | E10: =SUM(E4:E9) -> 1087128 | F10: 718920 | G10: 914405 | H10: 826766
A11: Property and equipment, net | B11: 71097 | C11: 82610 | D11: 78075 | E11: 119044 | F11: 124587 | G11: 130714 | H11: 126270
A12: Operating lease right-of-use assets | C12: 37768 | D12: 34090 | E12: 54971 | F12: 55406 | G12: 77556 | H12: 78279
A13: Goodwill | B13: 54293 | C13: 51293 | D13: 54293 | E13: 54293 | F13: 54293 | G13: 54293 | H13: 72557
A14: Intangible assets, net | B14: 80019 | C14: 90850 | D14: 92078 | E14: 95314 | F14: 99429 | G14: 117629 | H14: 172023
A15: Deferred income taxes | B15: 7777 | C15: 1082 | D15: 1062
A16: Deferred charges and other assets | B16: 1014 | C16: 2389 | D16: 972 | E16: 2575 | F16: 24130 | G16: 2595 | H16: 10225
A17: Long Term Assets | B17: =B19-B10 -> 217200 | C17: =C19-C10 -> 268992 | D17: =D19-D10 -> 260570 | E17: =E19-E10 -> 9236 | F17: =F19-F10 -> 357845 | G17: =G19-G10 -> 382787 | H17: =H19-H10 -> 459354
A18: Average Long Term Assets | C18: =(C17+B17)/2 -> 243096 | D18: =(D17+C17)/2 -> 264781 | E18: =(E17+D17)/2 -> 134903 | F18: =(F17+E17)/2 -> 183540.5 | G18: =(G17+F17)/2 -> 370316 | H18: =(H17+G17)/2 -> 421070.5
A19: TOTAL ASSETS | B19: 514213 | C19: 629539 | D19: 737067 | E19: 1096364 | F19: 1076765 | G19: 1297192 | H19: 1286120
A20: Average Total Assets | B20: na | C20: =(C19+B19)/2 -> 571876 | D20: =(D19+C19)/2 -> 683303 | E20: =(E19+D19)/2 -> 916715.5 | F20: =(F19+E19)/2 -> 1086564.5 | G20: =(G19+F19)/2 -> 1186978.5 | H20: =(H19+G19)/2 -> 1291656
A21: Current liabilities:
A22: Accounts payable | B22: 68737 | C22: 83823 | D22: 123621 | E22: 191319 | F22: 140818 | G22: 130392 | H22: 158499
A23: Accrued expenses and other current liabilities | B23: 53022 | C23: 42088 | D23: 89068 | E23: 132309 | F23: 211399 | G23: 130026 | H23: 128210
A24: Taxes payable | B24: 6390 | C24: 3329 | D24: 18316 | E24: 14514 | F24: 15289 | G24: 33489 | H24: 38089
A25: Accrued payroll and related costs | B25: 15551 | C25: 18119 | D25: 25810 | E25: 30844 | F25: 4847 | G25: 23141 | H25: 28610
A26: Operating lease liabilities | C26: 7768 | D26: 8247 | E26: 10167 | F26: 120076 | G26: 14726 | H26: 19621
A27: Current maturities of long-term debt | B27: 43638 | C27: 15185 | D27: 22697 | E27: 24560 | F27: 24611 | G27: 6579 | H27: 6475
A28: CURRENT LIABILITIES | B28: 187338 | C28: 170312 | D28: 287759 | E28: 403713 | F28: 409040 | G28: 398353 | H28: 379504
A29: Long-term debt, net of current portion | B29: 284376 | C29: 281715 | D29: 111017 | E29: 95741 | F29: 71741 | G29: 78645 | H29: 72821
A30: Operating lease liabilities, non-current | C30: 42200 | D30: 36546 | E30: 55940 | F30: 55649 | G30: 76163 | H30: 73586
A31: Other liabilities | B31: 13528 | C31: 13307 | D31: 13327 | E31: 23147 | F31: 13858 | G31: 20421 | H31: 20102
A33: LONG-TERM LIABILITIES | B33: =SUM(B29:B31) -> 297904 | C33: =SUM(C29:C31) -> 337222 | D33: =SUM(D29:D31) -> 160890 | E33: =SUM(E29:E31) -> 174828 | F33: =SUM(F29:F31) -> 141248 | G33: =SUM(G29:G31) -> 175229 | H33: =SUM(H29:H31) -> 166509
A35: TOTAL LIABILITIES | B35: 485242 | C35: 507534 | D35: 448649 | E35: 578541 | F35: 550288 | G35: 573582 | H35: 546013
A36: Commitments and contingencies
A37: Stockholders' equity:
A38: Common stock, $0.01 par value | B38: 842 | C38: 868 | D38: 871 | E38: 877 | F38: 881 | G38: 886 | H38: 892
A39: Treasury stock, at cost | F39: -100025 | G39: -100025 | H39: -281587
A40: Preferred stock, $10 par value | B40: 0 | C40: 0 | D40: 0 | E40: 0 | F40: 0 | G40: 0 | H40: 0
A41: Additional paid-in capital | B41: 268327 | C41: 310678 | D41: 321744 | E41: 337735 | F41: 357490 | G41: 386377 | H41: 405921
A42: Retained Earnings | B42: -240104 | C42: -189545 | D42: -33744 | E42: 178858 | F42: 268551 | G42: 438436 | H42: 614125
...

Sheet Base Case Projections
A1: Yeti Holdings, Base Case Projections
B2: Actuals | E2: Projections for
B3: EOY 2024 | D3: Assumptions | E3: 2025 | F3: 2026 | G3: 2027 | H3: 2028 | I3: 2029
C4: % of Revenue | D4: Expected Revenue Growth Rate | E4: 0 | F4: 0 | G4: 0 | H4: 0 | I4: 0
A5: Net revenues | B5: ='Income Statements'!H6 -> 1829873 | C5: =B5/B5 -> 1 | D5: Projected Revenue | E5: =B5*(1+E4) -> 1829873 | F5: =E5*(1+F4) -> 1829873 | G5: =F5*(1+G4) -> 1829873 | H5: =G5*(1+H4) -> 1829873 | I5: =H5*(1+I4) -> 1829873
A6: Cost of goods sold (CGS) | B6: ='Income Statements'!H7 -> 766589 | C6: =B6/B5 -> 0.41893017 | D6: Product CGS Percent of Revenue | E6: =B6/B5 -> 0.41893017 | F6: =E6 -> 0.41893017 | G6: =F6 -> 0.41893017 | H6: =G6 -> 0.41893017 | I6: =H6 -> 0.41893017
D7: Projected Cost of Goods Sold | E7: =E5*E6 -> 766589 | F7: =E5*F6 -> 766589 | G7: =F5*G6 -> 766589 | H7: =G5*H6 -> 766589 | I7: =H5*I6 -> 766589
A8: Selling, general and administrative expenses | B8: ='Income Statements'!H10 -> 817908 | C8: =B8/B5 -> 0.44697528 | D8: S.G. & A/Revenue | E8: =B8/B5 -> 0.44697528 | F8: =E8 -> 0.44697528 | G8: =F8 -> 0.44697528 | H8: =G8 -> 0.44697528 | I8: =H8 -> 0.44697528
D9: Projected S.G.&A. | E9: =E8*E5 -> 817908 | F9: =F8*F5 -> 817908 | G9: =G8*G5 -> 817908 | H9: =H8*H5 -> 817908 | I9: =I8*I5 -> 817908
A11: Income (Loss) from operations (EBIT) | B11: ='Income Statements'!H11 -> 245376 | C11: =B11/B5 -> 0.13409455 | D11: Projected EBIT | E11: =E5-E7-E9 -> 245376 | F11: =F5-F7-F9 -> 245376 | G11: =G5-G7-G9 -> 245376 | H11: =H5-H7-H9 -> 245376 | I11: =I5-I7-I9 -> 245376
A12: Interest expense, net | B12: ='Income Statements'!H12 -> 660 | C12: =B12/B5 -> 0.00036068077 | D12: Frozen at 2023 Levels | E12: =B12 -> 660 | F12: =E12 -> 660 | G12: =F12 -> 660 | H12: =G12 -> 660 | I12: =H12 -> 660
A13: Earnings before income taxes (EBT) | B13: ='Income Statements'!H14 -> 232848 | C13: =B13/B5 -> 0.12724818 | D13: Projected EBT | E13: =E11-E12 -> 244716 | F13: =F11-F12 -> 244716 | G13: =G11-G12 -> 244716 | H13: =H11-H12 -> 244716 | I13: =I11-I12 -> 244716
D14: Income Tax Rate | E14: =C16 -> 0.096011581 | F14: =E14 -> 0.096011581 | G14: =F14 -> 0.096011581 | H14: =G14 -> 0.096011581 | I14: =H14 -> 0.096011581
A15: Provision for income taxes | B15: ='Income Statements'!H15 -> -57159 | C15: =B15/B5 -> -0.031236594 | D15: Projected Income Taxes | E15: =E14*E13 -> 23495.57 | F15: =F14*F13 -> 23495.57 | G15: =G14*G13 -> 23495.57 | H15: =H14*H13 -> 23495.57 | I15: =I14*I13 -> 23495.57
A16: Net income after taxes (EAT) | B16: ='Income Statements'!H16 -> 175689 | C16: =B16/B5 -> 0.096011581 | D16: Projected Net Income After Taxes | E16: =E13-E15 -> 221220.43 | F16: =F13-F15 -> 221220.43 | G16: =G13-G15 -> 221220.43 | H16: =H13-H15 -> 221220.43 | I16: =I13-I15 -> 221220.43
A17: ='Balance Sheets'!H16 -> 10225
A18: Total assets | B18: ='Balance Sheets'!H16 -> 10225 | C18: =B18/B5 -> 0.0055878195 | D18: Projected Total Assets/Revenue | E18: =C18 -> 0.0055878195 | F18: =E18 -> 0.0055878195 | G18: =F18 -> 0.0055878195 | H18: =G18 -> 0.0055878195 | I18: =H18 -> 0.0055878195
D19: Projected Total Assets | E19: =E5*E18 -> 10225 | F19: =F5*F18 -> 10225 | G19: =G5*G18 -> 10225 | H19: =H5*H18 -> 10225 | I19: =I5*I18 -> 10225
A20: Total Liabilities | B20: ='Balance Sheets'!H32 -> 0 | C20: =B20/B5 -> 0 | D20: Projected Total Liabilities/Revenue | E20: =C20 -> 0 | F20: =E20 -> 0 | G20: =F20 -> 0 | H20: =G20 -> 0 | I20: =H20 -> 0
D21: Projected Total Liabilities | E21: =E20*E5 -> 0 | F21: =F20*F5 -> 0 | G21: =G20*G5 -> 0 | H21: =H20*H5 -> 0 | I21: =I20*I5 -> 0
A22: Total Stockholders Equity | B22: ='Balance Sheets'!H41 -> 405921 | D22: Projected Total Stockholders Equity | E22: =B22+E16 -> 627141.43 | F22: =E22+F16 -> 848361.86 | G22: =F22+G16 -> 1069582.3 | H22: =G22+H16 -> 1290802.7 | I22: =H22+I16 -> 1512023.1
B24: The "Bottom Line" | D24: Projected Net Capital Available | E24: =E21+E22-E19 -> 616916.43 | F24: =F21+F22-F19 -> 838136.86 | G24: =G21+G22-G19 -> 1059357.3 | H24: =H21+H22-H19 -> 1280577.7 | I24: =I21+I22-I19 -> 1501798.1
D26: Assumptions
D27: Calculated Values

Sheet Improved Case Projections
A1: Copy and paste your base case projections worksheet to this one. Then modify the assumptions to take into account the results of your recommendations.
