Workbook

Sheet Cover
A1: AAON, Inc. Three-Statement Financial Model
A3: Company: AAON, Inc.
A4: Ticker: AAON
A5: Industry: HVAC / Commercial & Industrial Equipment
A6: Model Type: Historical Financial Statements + Forecast Model
A7: Source: SEC filings and company annual reports

Sheet Sources
A1: Source | B1: Link/Description
A2: AAON Investor Relations | B2: Quarterly and annual reports page
A3: 2025 Annual Report / Form 10-K | B3: AAON Fiscal Year 2025 Annual Report
A4: 2024 Annual Report / Form 10-K | B4: AAON Fiscal Year 2024 Annual Report

Sheet Historical IS
A1: Income Statement
B2: 2021 | C2: 2022 | D2: 2023 | E2: 2024 | F2: 2025
A3: Net Sales | B3: 534517 | C3: 888788 | D3: 1168518 | E3: 1200635 | F3: 1442976
A4: Cost of Sales | B4: 396687 | C4: 651216 | D4: 769498 | E4: 803526 | F4: 1056352
A5: Gross Profit | B5: =B3-B4 -> 137830 | C5: =C3-C4 -> 237572 | D5: =D3-D4 -> 399020 | E5: =E3-E4 -> 397109 | F5: =F3-F4 -> 386624
A6: Selling, General & Administrative Expenses | B6: 68598 | C6: 110823 | D6: 171539 | E6: 188014 | F6: 239480
A7: Gain on disposal of assets | B7: -21 | C7: -12 | D7: -13 | E7: -23 | F7: -4
A8: Operating Income | B8: 69523 | C8: 126761 | D8: 227494 | E8: 209118 | F8: 146248
A9: Interest Expense | B9: -132 | C9: -2627 | D9: -4843 | E9: -2905 | F9: -17726
A10: Other income, net | B10: 61 | C10: 399 | D10: 503 | E10: 378 | F10: 230
A11: Income Before Taxes | B11: 69182 | C11: 124533 | D11: 223154 | E11: 206591 | F11: 128752
A12: Income Tax Provision | B12: 10424 | C12: 24157 | D12: 45531 | E12: 38032 | F12: 21159
A13: Net Income | B13: =B11-B12 -> 58758 | C13: =C11-C12 -> 100376 | D13: =D11-D12 -> 177623 | E13: =E11-E12 -> 168559 | F13: =F11-F12 -> 107593
A14: EPS
A15: Basic EPS | B15: 0.75 | C15: 1.26 | D15: 2.19 | E15: 2.07 | F15: 1.32
A16: Diluted EPS | B16: 0.73 | C16: 1.24 | D16: 2.13 | E16: 2.02 | F16: 1.29
A17: Cash dividends | B17: 0.25 | C17: 0.29 | D17: 0.32 | E17: 0.32 | F17: 0.4
A18: Weighted avg shares outstanding
A19: Basic | B19: 78606298 | C19: 79582480 | D19: 81156114 | E19: 81473131 | F19: 81529140
A20: Diluted | B20: 80593484 | C20: 81145610 | D20: 83295290 | E20: 83629502 | F20: 83105538

Sheet Historical BS
A1: Balance Sheet
A3: Assets | B3: 2021 | C3: 2022 | D3: 2023 | E3: 2024 | F3: 2025
A4: Cash & Cash Equivalents | B4: 2859 | C4: 5451 | D4: 287 | E4: 14 | F4: 13
A5: Restricted Cash | B5: 628 | C5: 498 | D5: 8736 | E5: 6500 | F5: 1226
A6: Accounts Receivable, net | B6: 70780 | C6: 127158 | D6: 138108 | E6: 147434 | F6: 314387
A7: Income tax receivable | B7: 5723 | C7: - | D7: 0 | E7: 4115 | F7: 27445
A8: Inventory, net | B8: 130270 | C8: 198939 | D8: 213532 | E8: 187420 | F8: 261151
A9: Contract assets, net | B9: 5749 | C9: 15151 | D9: 45194 | E9: 135421 | F9: 247037
A10: Prepaid expenses and other | B10: 2071 | C10: 1919 | D10: 3097 | E10: 7308 | F10: 17921
A11: Total current assets | B11: =SUM(B4:B10) -> 218080 | C11: =SUM(C4:C10) -> 349116 | D11: =SUM(D4:D10) -> 408954 | E11: =SUM(E4:E10) -> 488212 | F11: =SUM(F4:F10) -> 869180
A12: PP&E, net | B12: 258062 | C12: 304745 | D12: 369947 | E12: 510356 | F12: 631262
A13: Intangible assets, net and goodwill | B13: =70121+85727 -> 155848 | C13: =64606+81892 -> 146498 | D13: 149945 | E13: 160152 | F13: 165799
A14: Right of use assets | B14: 16974 | C14: 7123 | D14: 11774 | E14: 15436 | F14: 17988
A15: Other long-term assets | B15: 1216 | C15: 6421 | D15: 816 | E15: 242 | F15: 2281
A16: Deferred tax assets | B16: - | C16: - | D16: 0 | E16: 836 | F16: 0
A17: TOTAL ASSETS | B17: =SUM(B11:B16) -> 650180 | C17: =SUM(C11:C16) -> 813903 | D17: =SUM(D11:D16) -> 941436 | E17: =SUM(E11:E16) -> 1175234 | F17: =SUM(F11:F16) -> 1686510
A19: Liabilities and Stockholders' Equity
A20: Current Liabilities
A21: Debt, short term | B21: 0 | C21: 0 | D21: 0 | E21: 16000 | F21: 0
A22: Short term obligations of NMTC | B22: 0 | C22: 0 | D22: 0 | E22: 0 | F22: 7535
A23: Accounts payable | B23: 29020 | C23: 45513 | D23: 27484 | E23: 44645 | F23: 110437
A24: Accrued liabilities | B24: 50206 | C24: 78630 | D24: 85508 | E24: 99347 | F24: 132213
A25: Contract liabilities | B25: 7542 | C25: 21424 | D25: 13757 | E25: 14913 | F25: 80670
A26: Total current liabilities | B26: =SUM(B21:B25) -> 86768 | C26: =SUM(C21:C25) -> 145567 | D26: =SUM(D21:D25) -> 126749 | E26: =SUM(E21:E25) -> 174905 | F26: =SUM(F21:F25) -> 330855
A27: Debt, long term | B27: =40000 -> 40000 | C27: 71004 | D27: 38328 | E27: 138981 | F27: 398320
A28: Deferred tax liabilities | B28: =31993 -> 31993 | C28: 18661 | D28: 12134 | E28: 0 | F28: 30313
A29: Other long term liabilities | B29: =18843 -> 18843 | C29: 11508 | D29: 16807 | E29: 20743 | F29: 23299
A30: New market tax credit obligations | B30: =6406 -> 6406 | C30: 6449 | D30: 12194 | E30: 16113 | F30: 8738
A31: Total Liabilities | B31: =SUM(B26:B30) -> 184010 | C31: =SUM(C26:C30) -> 253189 | D31: =SUM(D26:D30) -> 206212 | E31: =SUM(E26:E30) -> 350742 | F31: =SUM(F26:F30) -> 791525
A32: Stockholders equity
A33: Preferred stock | B33: 0 | C33: 0 | D33: 0 | E33: 0 | F33: 0
A34: Common stock | B34: 210 | C34: 322 | D34: 326 | E34: 326 | F34: 327
A35: APIC | B35: 81654 | C35: 98735 | D35: 122063 | E35: 68946 | F35: 64358
A36: Retained earnings | B36: 384306 | C36: 461657 | D36: 612835 | E36: 755310 | F36: 830300
A37: Total stockholders' equity | B37: =SUM(B33:B36) -> 466170 | C37: =SUM(C33:C36) -> 560714 | D37: =SUM(D33:D36) -> 735224 | E37: =SUM(E33:E36) -> 824582 | F37: =SUM(F33:F36) -> 894985
A38: Total liabilities and stockholders' equity | B38: =B37+B31 -> 650180 | C38: =C31+C37 -> 813903 | D38: =D31+D37 -> 941436 | E38: =E31+E37 -> 1175324 | F38: =F31+F37 -> 1686510

Sheet Historical CF
A1: Cash Flow
B2: 2021 | C2: 2022 | D2: 2023 | E2: 2024 | F2: 2025
A3: Operating Activities
A4: Net Income | B4: 58758 | C4: 100376 | D4: 177623 | E4: 168559 | F4: 107593
A5: Depreciation and amortization | B5: 30343 | C5: 35106 | D5: 46468 | E5: 62735 | F5: 79191
A6: Amortixsyion of debt insurance costs | B6: 43 | C6: 43 | D6: 82 | E6: 154 | F6: 394
A7: Amortizatino of right of use assets | B7: 73 | C7: 324 | D7: 324 | E7: 189 | F7: 166
A8: Provision; loss on AR, net of adjustments | B8: 43 | C8: -72 | D8: -154 | E8: 715 | F8: 70
A9: Provision; loss on contract assets | B9: 0 | C9: 0 | D9: 0 | E9: 399 | F9: 200
A10: Provision; excess and obsolete inventory, net of write-offs | B10: 629 | C10: 2740 | D10: 1633 | E10: -968 | F10: 152
A11: Share based compensation | B11: 11812 | C11: 13700 | D11: 16384 | E11: 16729 | F11: 17994
A12: Other | B12: -46 | C12: =-12+41-22 -> 7 | D12: -44 | E12: -4 | F12: -15
A13: Deferred income taxes | B13: 3669 | C13: -13332 | D13: -6527 | E13: -6606 | F13: 31149
A14: Changes in assets and liabilities
A15: Accounts receivable | B15: -9737 | C15: -56306 | D15: -9978 | E15: -10041 | F15: -167023
A16: Income tax receivable | B16: -1136 | C16: 18195 | D16: -11302 | E16: -5285 | F16: -23330
A17: Inventories | B17: -45955 | C17: -71409 | D17: -16226 | E17: 27080 | F17: -73883
A18: Contract assets | B18: 1886 | C18: -9402 | D18: -30043 | E18: -90626 | F18: -111816
A19: Prepaid expenses and other long-term assets | B19: 1374 | C19: -2367 | D19: -1048 | E19: -3707 | F19: -11673
A20: Accounts payable | B20: 10899 | C20: 11574 | D20: -18316 | E20: 16959 | F20: 52904
A21: Contract liabilities | B21: -229 | C21: 13882 | D21: -7667 | E21: 1156 | F21: 65757
A22: Extended warranties | B22: 447 | C22: 1314 | D22: 2600 | E22: 1835 | F22: 831
A23: Accrued liabilities and other long term liabilities | B23: -1690 | C23: 16945 | D23: 15086 | E23: 13259 | F23: 31873
A24: Net cash from operating activities | B24: =SUM(B4:B23) -> 61183 | C24: =SUM(C4:C23) -> 61318 | D24: =SUM(D4:D23) -> 158895 | E24: =SUM(E4:E23) -> 192532 | F24: =SUM(F4:F23) -> 534
A26: Investing Activities
A27: Capital expenditures | B27: -55362 | C27: -54024 | D27: -104294 | E27: -195660 | F27: -190563
A28: Cash paid for building | B28: 0 | C28: -22000 | D28: 0 | E28: 0 | F28: 0
A29: Cash paid in business combo, net of cash acquired | B29: -103430 | C29: -249 | D29: 0 | E29: 0 | F29: 0
A30: Proceeds from government incentive grant | B30: 0 | D30: 0 | E30: 0 | F30: 12000
A31: Proceeds from sale of PP&E | B31: 19 | C31: 12 | D31: 129 | E31: 25 | F31: 40
A32: Acquisition of intangible assets | B32: 0 | C32: 0 | D32: -5197 | E32: -17491 | F32: -14329
A33: Principal payments from note receivable | B33: 54 | C33: 48 | D33: 51 | E33: 51 | F33: 435
A34: Net cash used in investing activities | B34: =SUM(B27:B33) -> -158719 | C34: =SUM(C27:C33) -> -76213 | D34: -109311 | E34: -213075 | F34: -192417
A35: Financing Activities
A36: Borrowings of debt | B36: 40000 | C36: 225758 | D36: 597111 | E36: 717897 | F36: 915391
A37: Payment of debt | B37: 0 | C37: -194754 | D37: -629787 | E37: -601091 | F37: -672204
A38: Proceeds from financing obligations, net of insurance costs | B38: 0 | C38: 0 | D38: 6061 | E38: 4186 | F38: 0
A39: Payment related to financing costs | B39: 0 | C39: 0 | D39: -398 | E39: -664 | F39: -1395
A40: Stock options exercised | B40: 21148 | C40: 23140 | D40: 33259 | E40: 31861 | F40: 17144
A41: Repurchase of stock - open market | B41: -20876 | C41: -12737 | D41: -25009 | E41: -100034 | F41: -29995
...

Sheet Assumptions
A1: Forecast Assumptions
A3: Assumption | B3: 2022 | C3: 2023 | D3: 2024 | E3: 2025 | F3: Average | G3: Notes
A4: Revenue Growth | B4: =('Historical IS'!C3/'Historical IS'!B3)-1 -> 0.66278715 | C4: =('Historical IS'!D3/'Historical IS'!C3)-1 -> 0.31473197 | D4: =('Historical IS'!E3/'Historical IS'!D3)-1 -> 0.027485242 | E4: =('Historical IS'!F3/'Historical IS'!E3)-1 -> 0.20184402 | F4: =AVERAGE(B4:E4) -> 0.3017121 | G4: % Growth
A5: Gross Margin | B5: ='Historical IS'!C5/'Historical IS'!C3 -> 0.26729884 | C5: ='Historical IS'!D5/'Historical IS'!D3 -> 0.34147527 | D5: ='Historical IS'!E5/'Historical IS'!E3 -> 0.33074915 | E5: ='Historical IS'!F5/'Historical IS'!F3 -> 0.26793516 | F5: =AVERAGE(B5:E5) -> 0.3018646 | G5: % of Revenue
A6: SG&A % of Revenue | B6: ='Historical IS'!C6/'Historical IS'!C3 -> 0.12469003 | C6: ='Historical IS'!D6/'Historical IS'!D3 -> 0.14680048 | D6: ='Historical IS'!E6/'Historical IS'!E3 -> 0.15659547 | E6: ='Historical IS'!F6/'Historical IS'!F3 -> 0.16596257 | F6: =AVERAGE(B6:E6) -> 0.14851213 | G6: % of Revenue
A7: Tax Rate | B7: ='Historical IS'!C12/'Historical IS'!C11 -> 0.19398071 | C7: ='Historical IS'!D12/'Historical IS'!D11 -> 0.20403399 | D7: ='Historical IS'!E12/'Historical IS'!E11 -> 0.18409321 | E7: ='Historical IS'!F12/'Historical IS'!F11 -> 0.16433919 | F7: =AVERAGE(B7:E7) -> 0.18661178 | G7: Effective Tax Rate
A8: CapEx % of Revenue | B8: =ABS('Historical CF'!C27)/'Historical IS'!C3 -> 0.060783899 | C8: =ABS('Historical CF'!D27)/'Historical IS'!D3 -> 0.089253225 | D8: =ABS('Historical CF'!E27)/'Historical IS'!E3 -> 0.16296377 | E8: =ABS('Historical CF'!F27)/'Historical IS'!F3 -> 0.13206249 | F8: =AVERAGE(B8:E8) -> 0.11126584 | G8: Capital Spending
A9: Depreciation % of PP&E | B9: ='Historical CF'!C5/'Historical BS'!B12 -> 0.13603708 | C9: ='Historical CF'!D5/'Historical BS'!C12 -> 0.15248158 | D9: ='Historical CF'!E5/'Historical BS'!D12 -> 0.16957835 | E9: ='Historical CF'!F5/'Historical BS'!E12 -> 0.15516816 | F9: =AVERAGE(B9:E9) -> 0.15331629 | G9: Depreciation
A10: AR Days | B10: =('Historical BS'!C6/'Historical IS'!C3)*365 -> 52.220181 | C10: =('Historical BS'!D6/'Historical IS'!D3)*365 -> 43.139618 | D10: =('Historical BS'!E6/'Historical IS'!E3)*365 -> 44.820791 | E10: =('Historical BS'!F6/'Historical IS'!F3)*365 -> 79.524022 | F10: =AVERAGE(B10:E10) -> 54.926153 | G10: Days Sales Outstanding
A11: Inventory Days | B11: =('Historical BS'!C8/'Historical IS'!C4)*365 -> 111.5033 | C11: =('Historical BS'!D8/'Historical IS'!D4)*365 -> 101.28575 | D11: =('Historical BS'!E8/'Historical IS'!E4)*365 -> 85.135142 | E11: =('Historical BS'!F8/'Historical IS'!F4)*365 -> 90.235182 | F11: =AVERAGE(B11:E11) -> 97.039844 | G11: Days Inventory Outstanding
A12: AP Days | B12: =('Historical BS'!C23/'Historical IS'!C4)*365 -> 25.509577 | C12: =('Historical BS'!D23/'Historical IS'!D4)*365 -> 13.036629 | D12: =('Historical BS'!E23/'Historical IS'!E4)*365 -> 20.279898 | E12: =('Historical BS'!F23/'Historical IS'!F4)*365 -> 38.15916 | F12: =AVERAGE(B12:E12) -> 24.246316 | G12: Days Payable Outstanding
A14: Forecast Revenue Growth | F14: 0.1
A15: Forecast Gross Margin | F15: 0.28
A16: Forecast SG&A % | F16: 0.16
A17: Forecast Tax Rate | F17: 0.19

Sheet Forecast IS
A1: Forecast Income Statement
B2: 2025A | C2: 2026E | D2: 2027E | E2: 2028E | G2: A=Actual
A3: Net Sales | B3: ='Historical IS'!F3 -> 1442976 | C3: =B3*(1+Assumptions!F14) -> 1587273.6 | D3: =C3*(1+Assumptions!F14) -> 1746001 | E3: =D3*(1+Assumptions!F14) -> 1920601.1 | G3: E = Estimate
A4: Cost of Sales | B4: ='Historical IS'!F4 -> 1056352 | C4: =C3-C5 -> 1142837 | D4: =D3-D5 -> 1257120.7 | E4: =E3-E5 -> 1382832.8
A5: Gross Profit | B5: ='Historical IS'!F5 -> 386624 | C5: =C3*Assumptions!$F$15 -> 444436.61 | D5: =D3*Assumptions!$F$15 -> 488880.27 | E5: =E3*Assumptions!$F$15 -> 537768.3
A6: Selling, General & Administrative Expenses | B6: ='Historical IS'!F6 -> 239480 | C6: =C3*Assumptions!$F$16 -> 253963.78 | D6: =D3*Assumptions!$F$16 -> 279360.15 | E6: =E3*Assumptions!$F$16 -> 307296.17
A7: Gain on disposal of assets | B7: ='Historical IS'!F7 -> -4 | C7: 0 | D7: 0 | E7: 0
A8: Operating Income | B8: ='Historical IS'!F8 -> 146248 | C8: =C5-C6+C7 -> 190472.83 | D8: =D5-D6+D7 -> 209520.12 | E8: =E5-E6+E7 -> 230472.13
A9: Interest Expense | B9: ='Historical IS'!F9 -> -17726 | C9: =B9 -> -17726 | D9: =C9 -> -17726 | E9: =D9 -> -17726
A10: Other income, net | B10: ='Historical IS'!F10 -> 230 | C10: 0 | D10: 0 | E10: 0
A11: Income Before Taxes | B11: ='Historical IS'!F11 -> 128752 | C11: =C8+C9+C10 -> 172746.83 | D11: =D8+D9+D10 -> 191794.12 | E11: =E8+E9+E10 -> 212746.13
A12: Income Tax Provision | B12: ='Historical IS'!F12 -> 21159 | C12: =C11*Assumptions!$F$17 -> 32821.898 | D12: =D11*Assumptions!$F$17 -> 36440.882 | E12: =E11*Assumptions!$F$17 -> 40421.764
A13: Net Income | B13: ='Historical IS'!F13 -> 107593 | C13: =C11-C12 -> 139924.93 | D13: =D11-D12 -> 155353.23 | E13: =E11-E12 -> 172324.36
A15: Gross Margin % | B15: =B5/B3 -> 0.26793516 | C15: =C5/C3 -> 0.28 | D15: =D5/D3 -> 0.28 | E15: =E5/E3 -> 0.28
A16: Operating Margin % | B16: =B8/B3 -> 0.10135165 | C16: =C8/C3 -> 0.12 | D16: =D8/D3 -> 0.12 | E16: =E8/E3 -> 0.12

Sheet Executive Dashboard
A1: AAON Financial Modeling & Forecasting Dashboard
A2: Historical Performance (2021–2025) & Forecast (2026–2028)
A5: Revenue | C5: Net Income | E5: Gross Margin | G5: Operating Margin
A6: ='Forecast IS'!E3 -> 1920601.1 | C6: ='Forecast IS'!E13 -> 172324.36 | E6: ='Forecast IS'!E5/'Forecast IS'!E3 -> 0.28 | G6: ='Forecast IS'!E8/'Forecast IS'!E3 -> 0.12
A8: Revenue Growth | C8: Effective Tax Rate
A9: =('Forecast IS'!E3/'Forecast IS'!D3)-1 -> 0.1 | C9: ='Forecast IS'!E12/'Forecast IS'!E11 -> 0.19
